127.0.0.1:53428: Traceback (most recent call last):
  File "/usr/local/lib/python3.8/dist-packages/seleniumwire/thirdparty/mitmproxy/net/tcp.py", line 92, in write
    return self.o.sendall(v)
  File "/usr/local/lib/python3.8/dist-packages/OpenSSL/SSL.py", line 1929, in sendall
    self._raise_ssl_error(self._ssl, result)
  File "/usr/local/lib/python3.8/dist-packages/OpenSSL/SSL.py", line 1699, in _raise_ssl_error
    raise SysCallError(errno, errorcode.get(errno))
OpenSSL.SSL.SysCallError: (32, 'EPIPE')

During handling of the above exception, another exception occurred:

Traceback (most recent call last):
  File "/usr/local/lib/python3.8/dist-packages/seleniumwire/thirdparty/mitmproxy/server/server.py", line 113, in handle
    root_layer()
  File "/usr/local/lib/python3.8/dist-packages/seleniumwire/thirdparty/mitmproxy/server/modes/http_proxy.py", line 23, in __call__
    layer()
  File "/usr/local/lib/python3.8/dist-packages/seleniumwire/thirdparty/mitmproxy/server/protocol/tls.py", line 285, in __call__
    layer()
  File "/usr/local/lib/python3.8/dist-packages/seleniumwire/thirdparty/mitmproxy/server/protocol/http1.py", line 100, in __call__
    layer()
  File "/usr/local/lib/python3.8/dist-packages/seleniumwire/thirdparty/mitmproxy/server/protocol/http.py", line 206, in __call__
    if not self._process_flow(flow):
  File "/usr/local/lib/python3.8/dist-packages/seleniumwire/thirdparty/mitmproxy/server/protocol/http.py", line 288, in _process_flow
    return self.handle_upstream_connect(f)
  File "/usr/local/lib/python3.8/dist-packages/seleniumwire/thirdparty/mitmproxy/server/protocol/http.py", line 254, in handle_upstream_connect
    return layer()
  File "/usr/local/lib/python3.8/dist-packages/seleniumwire/thirdparty/mitmproxy/server/protocol/http.py", line 103, in __call__
    layer()
  File "/usr/local/lib/python3.8/dist-packages/seleniumwire/thirdparty/mitmproxy/server/protocol/tls.py", line 285, in __call__
    layer()
  File "/usr/local/lib/python3.8/dist-packages/seleniumwire/thirdparty/mitmproxy/server/protocol/http2.py", line 345, in __call__
    self._initiate_server_conn()
  File "/usr/local/lib/python3.8/dist-packages/seleniumwire/thirdparty/mitmproxy/server/protocol/http2.py", line 126, in _initiate_server_conn
    self.server_conn.send(self.connections[self.server_conn].data_to_send())
  File "/usr/local/lib/python3.8/dist-packages/seleniumwire/thirdparty/mitmproxy/connections.py", line 276, in send
    self.wfile.write(message)
  File "/usr/local/lib/python3.8/dist-packages/seleniumwire/thirdparty/mitmproxy/net/tcp.py", line 98, in write
    raise exceptions.TcpDisconnect(str(e))
seleniumwire.thirdparty.mitmproxy.exceptions.TcpDisconnect: (32, 'EPIPE')